<?xml version="1.0" encoding="utf-8"?>
<!-- This URDF was automatically created by SolidWorks to URDF Exporter! Originally created by Stephen Brawner (brawner@gmail.com) 
     Commit Version: 1.4.2-27-gc3b3358  Build Version: 1.4.6891.25992
     For more information, please see http://wiki.ros.org/sw_urdf_exporter -->
<robot
  name="resetrobotmetal">
  <link
    name="base_link">
    <inertial>
      <origin
        xyz="-0.048537 7.2262E-08 0.084952"
        rpy="0 0 0" />
      <mass
        value="21.435" />
      <inertia
        ixx="0.20713"
        ixy="2.0266E-07"
        ixz="0.0078532"
        iyy="0.40868"
        iyz="6.1248E-08"
        izz="0.50173" />
    </inertial>
    <visual>
      <origin
        xyz="0 0 0"
        rpy="0 0 0" />
      <geometry>
        <mesh
          filename="package://resetrobotmetal/meshes/base_link.STL" />
      </geometry>
      <material
        name="">
        <color
          rgba="0.79216 0.81961 0.93333 1" />
      </material>
    </visual>
    <collision>
      <origin
        xyz="0 0 0"
        rpy="0 0 0" />
      <geometry>
        <mesh
          filename="package://resetrobotmetal/meshes/base_link.STL" />
      </geometry>
    </collision>
  </link>
  <link
    name="link_1">
    <inertial>
      <origin
        xyz="0.058504 0.018758 0.15092"
        rpy="0 0 0" />
      <mass
        value="25.307" />
      <inertia
        ixx="0.32227"
        ixy="-0.047774"
        ixz="-0.10939"
        iyy="0.51973"
        iyz="-0.023513"
        izz="0.48216" />
    </inertial>
    <visual>
      <origin
        xyz="0 0 0"
        rpy="0 0 0" />
      <geometry>
        <mesh
          filename="package://resetrobotmetal/meshes/link_1.STL" />
      </geometry>
      <material
        name="">
        <color
          rgba="0.79216 0.81961 0.93333 1" />
      </material>
    </visual>
    <collision>
      <origin
        xyz="0 0 0"
        rpy="0 0 0" />
      <geometry>
        <mesh
          filename="package://resetrobotmetal/meshes/link_1.STL" />
      </geometry>
    </collision>
  </link>
  <joint
    name="joint_1"
    type="revolute">
    <origin
      xyz="0 0 0.181"
      rpy="0 0 0" />
    <parent
      link="base_link" />
    <child
      link="link_1" />
    <axis
      xyz="0 0 1" />
    <limit
      lower="-2.8798"
      upper="2.8798"
      effort="100"
      velocity="3" />
    <safety_controller
      k_velocity="0" />
  </joint>
  <link
    name="link_2">
    <inertial>
      <origin
        xyz="-0.016063 -0.28254 -0.079384"
        rpy="0 0 0" />
      <mass
        value="15.157" />
      <inertia
        ixx="0.85409"
        ixy="-0.0085112"
        ixz="-0.0041072"
        iyy="0.059494"
        iyz="-0.0050587"
        izz="0.86172" />
    </inertial>
    <visual>
      <origin
        xyz="0 0 0"
        rpy="0 0 0" />
      <geometry>
        <mesh
          filename="package://resetrobotmetal/meshes/link_2.STL" />
      </geometry>
      <material
        name="">
        <color
          rgba="0.79216 0.81961 0.93333 1" />
      </material>
    </visual>
    <collision>
      <origin
        xyz="0 0 0"
        rpy="0 0 0" />
      <geometry>
        <mesh
          filename="package://resetrobotmetal/meshes/link_2.STL" />
      </geometry>
    </collision>
  </link>
  <joint
    name="joint_2"
    type="revolute">
    <origin
      xyz="0.16933 -0.1005 0.21703"
      rpy="-1.57 0 0" />
    <parent
      link="link_1" />
    <child
      link="link_2" />
    <axis
      xyz="0 0 1" />
    <limit
      lower="-1.6581"
      upper="1.2217"
      effort="100"
      velocity="3" />
    <safety_controller
      k_velocity="0" />
  </joint>
  <link
    name="link_3">
    <inertial>
      <origin
        xyz="0.0062446 -0.075744 0.11093"
        rpy="0 0 0" />
      <mass
        value="9.9716" />
      <inertia
        ixx="0.10459"
        ixy="0.0035018"
        ixz="0.00046279"
        iyy="0.063616"
        iyz="-0.0056135"
        izz="0.10657" />
    </inertial>
    <visual>
      <origin
        xyz="0 0 0"
        rpy="0 0 0" />
      <geometry>
        <mesh
          filename="package://resetrobotmetal/meshes/link_3.STL" />
      </geometry>
      <material
        name="">
        <color
          rgba="0.79216 0.81961 0.93333 1" />
      </material>
    </visual>
    <collision>
      <origin
        xyz="0 0 0"
        rpy="0 0 0" />
      <geometry>
        <mesh
          filename="package://resetrobotmetal/meshes/link_3.STL" />
      </geometry>
    </collision>
  </link>
  <joint
    name="joint_3"
    type="revolute">
    <origin
      xyz="0 -0.65 0"
      rpy="0 0 0" />
    <parent
      link="link_2" />
    <child
      link="link_3" />
    <axis
      xyz="0 0 1" />
    <limit
      lower="-1.4835"
      upper="1.6581"
      effort="100"
      velocity="3" />
    <safety_controller
      k_velocity="0" />
  </joint>
  <link
    name="link_4">
    <inertial>
      <origin
        xyz="1.0311E-07 -0.0077856 0.27219"
        rpy="0 0 0" />
      <mass
        value="5.2559" />
      <inertia
        ixx="0.10349"
        ixy="1.103E-10"
        ixz="2.5492E-09"
        iyy="0.09162"
        iyz="0.0033244"
        izz="0.020021" />
    </inertial>
    <visual>
      <origin
        xyz="0 0 0"
        rpy="0 0 0" />
      <geometry>
        <mesh
          filename="package://resetrobotmetal/meshes/link_4.STL" />
      </geometry>
      <material
        name="">
        <color
          rgba="0.79216 0.81961 0.93333 1" />
      </material>
    </visual>
    <collision>
      <origin
        xyz="0 0 0"
        rpy="0 0 0" />
      <geometry>
        <mesh
          filename="package://resetrobotmetal/meshes/link_4.STL" />
      </geometry>
    </collision>
  </link>
  <joint
    name="joint_4"
    type="revolute">
    <origin
      xyz="0.131 -0.15574 0.1035"
      rpy="-1.57 0 -1.57" />
    <parent
      link="link_3" />
    <child
      link="link_4" />
    <axis
      xyz="0 0 1" />
    <limit
      lower="-3.1416"
      upper="3.1416"
      effort="100"
      velocity="3" />
    <safety_controller
      k_velocity="0" />
  </joint>
  <link
    name="link_5">
    <inertial>
      <origin
        xyz="0.0010269 0.030968 -2.2367E-10"
        rpy="0 0 0" />
      <mass
        value="1.2009" />
      <inertia
        ixx="0.003095"
        ixy="-5.2043E-05"
        ixz="5.0414E-10"
        iyy="0.0015215"
        iyz="-1.6327E-11"
        izz="0.00339" />
    </inertial>
    <visual>
      <origin
        xyz="0 0 0"
        rpy="0 0 0" />
      <geometry>
        <mesh
          filename="package://resetrobotmetal/meshes/link_5.STL" />
      </geometry>
      <material
        name="">
        <color
          rgba="0.79216 0.81961 0.93333 1" />
      </material>
    </visual>
    <collision>
      <origin
        xyz="0 0 0"
        rpy="0 0 0" />
      <geometry>
        <mesh
          filename="package://resetrobotmetal/meshes/link_5.STL" />
      </geometry>
    </collision>
  </link>
  <joint
    name="joint_5"
    type="revolute">
    <origin
      xyz="0 0 0.424"
      rpy="1.57 0 0" />
    <parent
      link="link_4" />
    <child
      link="link_5" />
    <axis
      xyz="0 0 1" />
    <limit
      lower="-2.0071"
      upper="2.0071"
      effort="100"
      velocity="3" />
    <safety_controller
      k_velocity="0" />
  </joint>
  <link
    name="link_6">
    <inertial>
      <origin
        xyz="0.00077466 6.605E-16 0.023833"
        rpy="0 0 0" />
      <mass
        value="0.33714" />
      <inertia
        ixx="0.00025264"
        ixy="-6.2443E-08"
        ixz="3.5945E-06"
        iyy="0.00025233"
        iyz="2.0826E-09"
        izz="0.00036265" />
    </inertial>
    <visual>
      <origin
        xyz="0 0 0"
        rpy="0 0 0" />
      <geometry>
        <mesh
          filename="package://resetrobotmetal/meshes/link_6.STL" />
      </geometry>
      <material
        name="">
        <color
          rgba="0.79216 0.81961 0.93333 1" />
      </material>
    </visual>
    <collision>
      <origin
        xyz="0 0 0"
        rpy="0 0 0" />
      <geometry>
        <mesh
          filename="package://resetrobotmetal/meshes/link_6.STL" />
      </geometry>
    </collision>
  </link>
  <joint
    name="joint_6"
    type="revolute">
    <origin
      xyz="0.0036667 0.10994 0"
      rpy="-1.57 0 0" />
    <parent
      link="link_5" />
    <child
      link="link_6" />
    <axis
      xyz="0.033333 0 0.99944" />
    <limit
      lower="-6.2832"
      upper="6.2832"
      effort="100"
      velocity="3" />
    <safety_controller
      k_velocity="0" />
  </joint>
  <link
    name="last_link">
    <inertial>
      <origin
        xyz="-1.6876E-05 -2.9501E-05 0.0067938"
        rpy="0 0 0" />
      <mass
        value="0.046343" />
      <inertia
        ixx="1.9745E-05"
        ixy="-1.1087E-07"
        ixz="2.1962E-09"
        iyy="1.8881E-05"
        iyz="3.8641E-09"
        izz="3.727E-05" />
    </inertial>
    <visual>
      <origin
        xyz="0 0 0"
        rpy="0 0 0" />
      <geometry>
        <mesh
          filename="package://resetrobotmetal/meshes/last_link.STL" />
      </geometry>
      <material
        name="">
        <color
          rgba="0.79216 0.81961 0.93333 1" />
      </material>
    </visual>
    <collision>
      <origin
        xyz="0 0 0"
        rpy="0 0 0" />
      <geometry>
        <mesh
          filename="package://resetrobotmetal/meshes/last_link.STL" />
      </geometry>
    </collision>
  </link>
  <joint
    name="last_joint"
    type="fixed">
    <origin
      xyz="0.0018 0 0.05397"
      rpy="0 0.03334 0" />
    <parent
      link="link_6" />
    <child
      link="last_link" />
    <axis
      xyz="0 0 0" />
    <safety_controller
      k_velocity="0" />
  </joint>
  <link
    name="metal_link">
    <inertial>
      <origin
        xyz="-0.019331 0.048862 0.035558"
        rpy="0 0 0" />
      <mass
        value="0.020605" />
      <inertia
        ixx="3.1408E-05"
        ixy="6.3105E-06"
        ixz="1.9318E-06"
        iyy="4.6486E-06"
        iyz="-6.0887E-06"
        izz="3.1434E-05" />
    </inertial>
    <visual>
      <origin
        xyz="0 0 0"
        rpy="0 0 0" />
      <geometry>
        <mesh
          filename="package://resetrobotmetal/meshes/metal_link.STL" />
      </geometry>
      <material
        name="">
        <color
          rgba="0.79216 0.81961 0.93333 1" />
      </material>
    </visual>
    <collision>
      <origin
        xyz="0 0 0"
        rpy="0 0 0" />
      <geometry>
        <mesh
          filename="package://resetrobotmetal/meshes/metal_link.STL" />
      </geometry>
    </collision>
  </link>
  <joint
    name="metal_joint"
    type="fixed">
    <origin
      xyz="-4.4615E-05 5.8841E-05 0.0472"
      rpy="0 0 0" />
    <parent
      link="last_link" />
    <child
      link="metal_link" />
    <axis
      xyz="0 0 0" />
    <safety_controller
      k_velocity="0" />
  </joint>
</robot>